<robot
  name="twolinkman_">
  <link
    name="base_link">
    <inertial>
      <origin
        xyz="0.019321 0.56657 -0.012593"
        rpy="0 0 0" />
      <mass
        value="0.5" />
      <inertia
        ixx="0.046499"
        ixy="-0.0017672"
        ixz="-9.1379E-05"
        iyy="0.00036871"
        iyz="-0.00018866"
        izz="0.046684" />
    </inertial>
    <visual>
      <origin
        xyz="0 0 0"
        rpy="0 0 0" />
      <geometry>
        <mesh
          filename="package://twolinkman_/meshes/base_link.STL" />
      </geometry>
      <material
        name="">
        <color
          rgba="0.79216 0.81961 0.93333 1" />
      </material>
    </visual>
    <collision>
      <origin
        xyz="0 0 0"
        rpy="0 0 0" />
      <geometry>
        <mesh
          filename="package://twolinkman_/meshes/base_link.STL" />
      </geometry>
    </collision>
  </link>
  <link
    name="rear_link">
    <inertial>
      <origin
        xyz="0.062837 0.17854 0.2032"
        rpy="0 0 0" />
      <mass
        value="0.3699" />
      <inertia
        ixx="0.0029957"
        ixy="-2.6933E-19"
        ixz="2.1864E-20"
        iyy="4.5696E-05"
        iyz="-1.5814E-16"
        izz="0.0030162" />
    </inertial>
    <visual>
      <origin
        xyz="0 0 0"
        rpy="0 0 0" />
      <geometry>
        <mesh
          filename="package://twolinkman_/meshes/rear_link.STL" />
      </geometry>
      <material
        name="">
        <color
          rgba="0.75294 0.75294 0.75294 1" />
      </material>
    </visual>
    <collision>
      <origin
        xyz="0 0 0"
        rpy="0 0 0" />
      <geometry>
        <mesh
          filename="package://twolinkman_/meshes/rear_link.STL" />
      </geometry>
    </collision>
  </link>
  <joint
    name="rear_joint"
    type="revolute">
    <origin
      xyz="0.027753 0.14131 0.66781"
      rpy="1.5648 0.00085216 4.9911E-05" />
    <parent
      link="base_link" />
    <child
      link="rear_link" />
    <axis
      xyz="0 0 0" />
    <limit
      effort="0"
      velocity="0" />
  </joint>
  <link
    name="front_link">
    <inertial>
      <origin
        xyz="0.062837 0.17854 0.2032"
        rpy="0 0 0" />
      <mass
        value="0.3699" />
      <inertia
        ixx="0.0029957"
        ixy="-1.9719E-19"
        ixz="-6.7895E-21"
        iyy="4.5696E-05"
        iyz="-1.561E-16"
        izz="0.0030162" />
    </inertial>
    <visual>
      <origin
        xyz="0 0 0"
        rpy="0 0 0" />
      <geometry>
        <mesh
          filename="package://twolinkman_/meshes/front_link.STL" />
      </geometry>
      <material
        name="">
        <color
          rgba="0.75294 0.75294 0.75294 1" />
      </material>
    </visual>
    <collision>
      <origin
        xyz="0 0 0"
        rpy="0 0 0" />
      <geometry>
        <mesh
          filename="package://twolinkman_/meshes/front_link.STL" />
      </geometry>
    </collision>
  </link>
  <joint
    name="front_joint"
    type="revolute">
    <origin
      xyz="0 -0.30239 0.0038399"
      rpy="-0.011862 2.2213E-17 5.0372E-17" />
    <parent
      link="rear_link" />
    <child
      link="front_link" />
    <axis
      xyz="0 0 0" />
    <limit
      effort="0"
      velocity="0" />
  </joint>
  <link
    name="load_link">
    <inertial>
      <origin
        xyz="-1.3878E-17 -2.7756E-17 -5.5511E-17"
        rpy="0 0 0" />
      <mass
        value="0.06545" />
      <inertia
        ixx="1.6362E-05"
        ixy="-4.2352E-22"
        ixz="0"
        iyy="1.6362E-05"
        iyz="-1.0588E-22"
        izz="1.6362E-05" />
    </inertial>
    <visual>
      <origin
        xyz="0 0 0"
        rpy="0 0 0" />
      <geometry>
        <mesh
          filename="package://twolinkman_/meshes/load_link.STL" />
      </geometry>
      <material
        name="">
        <color
          rgba="0.79216 0.81961 0.93333 1" />
      </material>
    </visual>
    <collision>
      <origin
        xyz="0 0 0"
        rpy="0 0 0" />
      <geometry>
        <mesh
          filename="package://twolinkman_/meshes/load_link.STL" />
      </geometry>
    </collision>
  </link>
  <joint
    name="load_joint"
    type="fixed">
    <origin
      xyz="0.064287 0.024272 0.20069"
      rpy="-0.86981 1.1271 0.31167" />
    <parent
      link="front_link" />
    <child
      link="load_link" />
    <axis
      xyz="0 0 0" />
  </joint>
</robot>